Workbook

Sheet נתונים
A1: סימולציה: מחיר מטרה מול השקעה ב-S&P 500
A3: נתוני הדירה (מחיר מטרה)
A4: מחיר רכישה (מחיר מטרה) | B4: 3000000
A5: מחיר שוק נוכחי (להשוואה / ערך ההנחה) | B5: 3500000
A6: עליית מחירי הדיור בפועל - שנתי (אזור/פרויקט) | B6: 0 | C6: שיעור עליית הערך השנתי הצפוי של הדירה - גם לחישוב שווי הדירה בעתיד וגם לבסיס מס שבח
A7: תקופת החזקה לבחינה (שנים) | B7: 7
A9: מימון - משכנתא
A10: אחוז מימון | B10: 0.9
A11: הון עצמי | B11: =B4*(1-B10) -> 300000
A12: סכום משכנתא | B12: =B4-B11 -> 2700000
A13: תקופת משכנתא (שנים) | B13: 30
A14: ריבית משכנתא שנתית (ממוצעת משוקללת) | B14: 0.048
A16: הוצאות חד-פעמיות ברכישה
A17: מדד תשומות הבנייה (לתקופת הבנייה) | B17: 80000
A18: שדרוגים | B18: 70000
A19: עו"ד והוצאות רכישה (כולל מס רכישה אם חל) | B19: 20000
A20: ריהוט ומזגנים | B20: 40000
A21: סה"כ הוצאות חד פעמיות | B21: =SUM(B17:B20) -> 210000
A22: סה"כ הון "ננעל" בדירה (הון עצמי + הוצאות חד פעמיות) | B22: =B11+B21 -> 510000
A24: הוצאות שוטפות חודשיות על הדירה
A25: ביטוח (מבנה + חיים) - חודשי | B25: 250
A26: ועד בית / אחזקה - חודשי | B26: 0
A27: סה"כ הוצאות שוטפות חודשי | B27: =B25+B26 -> 250
A29: שכירות
A30: שכר דירה נוכחי - אם תמשיך לגור בשכירות | B30: 6500 | C30: אם תקנה ותגור בדירה - זה שכר הדירה שתחסוך / שתשתמש לצורך השוואה
A31: עליית שכר דירה שנתית | B31: 0.02
A32: הכנסה משכירות חודשית - אם תשכיר את הדירה החדשה | B32: =B5*0.03/12 -> 8750
A33: חודשי ריקנות בשנה (ללא שוכר) | B33: 0.5 | C33: לדוגמה 0.5 = חצי חודש בשנה ללא שוכר
A35: מיסוי במכירת הדירה (מס שבח)
A36: שיעור מס שבח על רווח ההון | B36: 0.25 | C36: שיעור מס שבח סטנדרטי על מכירת דירה שאינה פטורה (בפועל בד"כ 25% מהרווח הריאלי)
A37: פטור ממס שבח - דירה יחידה? (1=פטור, 0=לא פטור) | B37: 1 | C37: ברוב פרויקטי מחיר מטרה מחויבים שזו תהיה דירתכם היחידה לכל תקופת ההגבלה, ולכן בד"כ פטור מלא
A39: שוק ההון
A40: תשואה שנתית ממוצעת - S&P 500 | B40: 0.1
A42: תוצאות מחושבות
A43: תשלום משכנתא חודשי (שפיצר) | B43: =-PMT(B14/12,B13*12,B12) -> 14165.965
A44: תשואה חודשית שקולה - S&P 500 | B44: =(1+B40)^(1/12)-1 -> 0.0079741404
A45: הנחה משוערת ממחיר השוק | B45: =B5-B4 -> 500000
A48: הערה: כל התאים הכחולים הם פרמטרים שניתן וכדאי לשנות. כל שאר התאים מחושבים אוטומטית.

Sheet לוח_סילוקין
A1: חודש | B1: יתרה בתחילת חודש | C1: תשלום חודשי | D1: ריבית | E1: קרן | F1: יתרה בסוף חודש
A2: 1 | B2: =נתונים!B12 -> 2700000 | C2: =נתונים!B43 -> 14165.965 | D2: =B2*נתונים!B14/12 -> 10800 | E2: =C2-D2 -> 3365.9646 | F2: =B2-E2 -> 2696634
A3: 2 | B3: =F2 -> 2696634 | C3: =נתונים!B43 -> 14165.965 | D3: =B3*נתונים!B14/12 -> 10786.536 | E3: =C3-D3 -> 3379.4284 | F3: =B3-E3 -> 2693254.6
A4: 3 | B4: =F3 -> 2693254.6 | C4: =נתונים!B43 -> 14165.965 | D4: =B4*נתונים!B14/12 -> 10773.018 | E4: =C4-D4 -> 3392.9461 | F4: =B4-E4 -> 2689861.7
A5: 4 | B5: =F4 -> 2689861.7 | C5: =נתונים!B43 -> 14165.965 | D5: =B5*נתונים!B14/12 -> 10759.447 | E5: =C5-D5 -> 3406.5179 | F5: =B5-E5 -> 2686455.1
A6: 5 | B6: =F5 -> 2686455.1 | C6: =נתונים!B43 -> 14165.965 | D6: =B6*נתונים!B14/12 -> 10745.821 | E6: =C6-D6 -> 3420.144 | F6: =B6-E6 -> 2683035
A7: 6 | B7: =F6 -> 2683035 | C7: =נתונים!B43 -> 14165.965 | D7: =B7*נתונים!B14/12 -> 10732.14 | E7: =C7-D7 -> 3433.8246 | F7: =B7-E7 -> 2679601.2
A8: 7 | B8: =F7 -> 2679601.2 | C8: =נתונים!B43 -> 14165.965 | D8: =B8*נתונים!B14/12 -> 10718.405 | E8: =C8-D8 -> 3447.5599 | F8: =B8-E8 -> 2676153.6
A9: 8 | B9: =F8 -> 2676153.6 | C9: =נתונים!B43 -> 14165.965 | D9: =B9*נתונים!B14/12 -> 10704.614 | E9: =C9-D9 -> 3461.3501 | F9: =B9-E9 -> 2672692.3
A10: 9 | B10: =F9 -> 2672692.3 | C10: =נתונים!B43 -> 14165.965 | D10: =B10*נתונים!B14/12 -> 10690.769 | E10: =C10-D10 -> 3475.1955 | F10: =B10-E10 -> 2669217.1
A11: 10 | B11: =F10 -> 2669217.1 | C11: =נתונים!B43 -> 14165.965 | D11: =B11*נתונים!B14/12 -> 10676.868 | E11: =C11-D11 -> 3489.0963 | F11: =B11-E11 -> 2665728
A12: 11 | B12: =F11 -> 2665728 | C12: =נתונים!B43 -> 14165.965 | D12: =B12*נתונים!B14/12 -> 10662.912 | E12: =C12-D12 -> 3503.0527 | F12: =B12-E12 -> 2662224.9
A13: 12 | B13: =F12 -> 2662224.9 | C13: =נתונים!B43 -> 14165.965 | D13: =B13*נתונים!B14/12 -> 10648.9 | E13: =C13-D13 -> 3517.0649 | F13: =B13-E13 -> 2658707.9
A14: 13 | B14: =F13 -> 2658707.9 | C14: =נתונים!B43 -> 14165.965 | D14: =B14*נתונים!B14/12 -> 10634.831 | E14: =C14-D14 -> 3531.1331 | F14: =B14-E14 -> 2655176.7
A15: 14 | B15: =F14 -> 2655176.7 | C15: =נתונים!B43 -> 14165.965 | D15: =B15*נתונים!B14/12 -> 10620.707 | E15: =C15-D15 -> 3545.2577 | F15: =B15-E15 -> 2651631.5
A16: 15 | B16: =F15 -> 2651631.5 | C16: =נתונים!B43 -> 14165.965 | D16: =B16*נתונים!B14/12 -> 10606.526 | E16: =C16-D16 -> 3559.4387 | F16: =B16-E16 -> 2648072
A17: 16 | B17: =F16 -> 2648072 | C17: =נתונים!B43 -> 14165.965 | D17: =B17*נתונים!B14/12 -> 10592.288 | E17: =C17-D17 -> 3573.6765 | F17: =B17-E17 -> 2644498.3
A18: 17 | B18: =F17 -> 2644498.3 | C18: =נתונים!B43 -> 14165.965 | D18: =B18*נתונים!B14/12 -> 10577.993 | E18: =C18-D18 -> 3587.9712 | F18: =B18-E18 -> 2640910.4
A19: 18 | B19: =F18 -> 2640910.4 | C19: =נתונים!B43 -> 14165.965 | D19: =B19*נתונים!B14/12 -> 10563.642 | E19: =C19-D19 -> 3602.3231 | F19: =B19-E19 -> 2637308.1
A20: 19 | B20: =F19 -> 2637308.1 | C20: =נתונים!B43 -> 14165.965 | D20: =B20*נתונים!B14/12 -> 10549.232 | E20: =C20-D20 -> 3616.7323 | F20: =B20-E20 -> 2633691.3
A21: 20 | B21: =F20 -> 2633691.3 | C21: =נתונים!B43 -> 14165.965 | D21: =B21*נתונים!B14/12 -> 10534.765 | E21: =C21-D21 -> 3631.1993 | F21: =B21-E21 -> 2630060.1
A22: 21 | B22: =F21 -> 2630060.1 | C22: =נתונים!B43 -> 14165.965 | D22: =B22*נתונים!B14/12 -> 10520.24 | E22: =C22-D22 -> 3645.7241 | F22: =B22-E22 -> 2626414.4
A23: 22 | B23: =F22 -> 2626414.4 | C23: =נתונים!B43 -> 14165.965 | D23: =B23*נתונים!B14/12 -> 10505.658 | E23: =C23-D23 -> 3660.307 | F23: =B23-E23 -> 2622754.1
A24: 23 | B24: =F23 -> 2622754.1 | C24: =נתונים!B43 -> 14165.965 | D24: =B24*נתונים!B14/12 -> 10491.016 | E24: =C24-D24 -> 3674.9482 | F24: =B24-E24 -> 2619079.1
A25: 24 | B25: =F24 -> 2619079.1 | C25: =נתונים!B43 -> 14165.965 | D25: =B25*נתונים!B14/12 -> 10476.317 | E25: =C25-D25 -> 3689.648 | F25: =B25-E25 -> 2615389.5
A26: 25 | B26: =F25 -> 2615389.5 | C26: =נתונים!B43 -> 14165.965 | D26: =B26*נתונים!B14/12 -> 10461.558 | E26: =C26-D26 -> 3704.4066 | F26: =B26-E26 -> 2611685.1
A27: 26 | B27: =F26 -> 2611685.1 | C27: =נתונים!B43 -> 14165.965 | D27: =B27*נתונים!B14/12 -> 10446.74 | E27: =C27-D27 -> 3719.2242 | F27: =B27-E27 -> 2607965.9
A28: 27 | B28: =F27 -> 2607965.9 | C28: =נתונים!B43 -> 14165.965 | D28: =B28*נתונים!B14/12 -> 10431.863 | E28: =C28-D28 -> 3734.1011 | F28: =B28-E28 -> 2604231.8
A29: 28 | B29: =F28 -> 2604231.8 | C29: =נתונים!B43 -> 14165.965 | D29: =B29*נתונים!B14/12 -> 10416.927 | E29: =C29-D29 -> 3749.0375 | F29: =B29-E29 -> 2600482.7
A30: 29 | B30: =F29 -> 2600482.7 | C30: =נתונים!B43 -> 14165.965 | D30: =B30*נתונים!B14/12 -> 10401.931 | E30: =C30-D30 -> 3764.0337 | F30: =B30-E30 -> 2596718.7
A31: 30 | B31: =F30 -> 2596718.7 | C31: =נתונים!B43 -> 14165.965 | D31: =B31*נתונים!B14/12 -> 10386.875 | E31: =C31-D31 -> 3779.0898 | F31: =B31-E31 -> 2592939.6
A32: 31 | B32: =F31 -> 2592939.6 | C32: =נתונים!B43 -> 14165.965 | D32: =B32*נתונים!B14/12 -> 10371.758 | E32: =C32-D32 -> 3794.2062 | F32: =B32-E32 -> 2589145.4
A33: 32 | B33: =F32 -> 2589145.4 | C33: =נתונים!B43 -> 14165.965 | D33: =B33*נתונים!B14/12 -> 10356.582 | E33: =C33-D33 -> 3809.383 | F33: =B33-E33 -> 2585336
A34: 33 | B34: =F33 -> 2585336 | C34: =נתונים!B43 -> 14165.965 | D34: =B34*נתונים!B14/12 -> 10341.344 | E34: =C34-D34 -> 3824.6205 | F34: =B34-E34 -> 2581511.4
A35: 34 | B35: =F34 -> 2581511.4 | C35: =נתונים!B43 -> 14165.965 | D35: =B35*נתונים!B14/12 -> 10326.046 | E35: =C35-D35 -> 3839.919 | F35: =B35-E35 -> 2577671.5
A36: 35 | B36: =F35 -> 2577671.5 | C36: =נתונים!B43 -> 14165.965 | D36: =B36*נתונים!B14/12 -> 10310.686 | E36: =C36-D36 -> 3855.2787 | F36: =B36-E36 -> 2573816.2
A37: 36 | B37: =F36 -> 2573816.2 | C37: =נתונים!B43 -> 14165.965 | D37: =B37*נתונים!B14/12 -> 10295.265 | E37: =C37-D37 -> 3870.6998 | F37: =B37-E37 -> 2569945.5
A38: 37 | B38: =F37 -> 2569945.5 | C38: =נתונים!B43 -> 14165.965 | D38: =B38*נתונים!B14/12 -> 10279.782 | E38: =C38-D38 -> 3886.1826 | F38: =B38-E38 -> 2566059.3
A39: 38 | B39: =F38 -> 2566059.3 | C39: =נתונים!B43 -> 14165.965 | D39: =B39*נתונים!B14/12 -> 10264.237 | E39: =C39-D39 -> 3901.7273 | F39: =B39-E39 -> 2562157.6
A40: 39 | B40: =F39 -> 2562157.6 | C40: =נתונים!B43 -> 14165.965 | D40: =B40*נתונים!B14/12 -> 10248.63 | E40: =C40-D40 -> 3917.3342 | F40: =B40-E40 -> 2558240.3
...

Sheet השוואה_חודשית
A1: חודש | B1: שנה | C1: תשלום משכנתא | D1: הוצאות שוטפות | E1: יתרת משכנתא | F1: שווי הדירה | G1: הון עצמי בדירה (לפני מס) | H1: שכ"ד חלופי (אם גר בשכירות) | I1: הכנסה משכירות (נטו ממקדמי ריקנות) | J1: תזרים פנוי - מסלול S&P (C) | K1: תזרים פנוי - מסלול השכרה (B) | L1: תיק S&P - מסלול C | M1: תיק S&P - מסלול B | N1: רווח הון לפני מס (אם נמכר היום) | O1: מס שבח (אם נמכר היום) | P1: שווי נטו - מסלול A (גר בדירה) | Q1: שווי נטו - מסלול B (משכיר את הדירה) | R1: שווי נטו - מסלול C (לא קונה, משקיע ב-S&P)
A2: 1 | B2: =ROUNDUP(A2/12,0) -> 1 | C2: =נתונים!B43 -> 14165.965 | D2: =נתונים!B27 -> 250 | E2: =INDEX(לוח_סילוקין!$F$2:$F$361,A2) -> 2696634 | F2: =נתונים!$B$5*(1+נתונים!$B$6)^(A2/12) -> 3500000 | G2: =F2-E2 -> 803365.96 | H2: =נתונים!B30*(1+נתונים!B31)^(B2-1) -> 6500 | I2: =נתונים!B32*(1-נתונים!B33/12)*(1+נתונים!B31)^(B2-1) -> 8385.4167 | J2: =(C2+D2)-H2 -> 7915.9646 | K2: =I2-H2 -> 1885.4167 | L2: =נתונים!B11*(1+נתונים!B44)+J2 -> 310308.21 | M2: =0*(1+נתונים!B44)+K2 -> 1885.4167 | N2: =F2-(נתונים!B4+נתונים!B21) -> 290000 | O2: =MAX(0,N2)*נתונים!B36*(1-נתונים!B37) -> 0 | P2: =G2-O2 -> 803365.96 | Q2: =G2-O2+M2 -> 805251.38 | R2: =L2 -> 310308.21
A3: 2 | B3: =ROUNDUP(A3/12,0) -> 1 | C3: =נתונים!B43 -> 14165.965 | D3: =נתונים!B27 -> 250 | E3: =INDEX(לוח_סילוקין!$F$2:$F$361,A3) -> 2693254.6 | F3: =נתונים!$B$5*(1+נתונים!$B$6)^(A3/12) -> 3500000 | G3: =F3-E3 -> 806745.39 | H3: =נתונים!B30*(1+נתונים!B31)^(B3-1) -> 6500 | I3: =נתונים!B32*(1-נתונים!B33/12)*(1+נתונים!B31)^(B3-1) -> 8385.4167 | J3: =(C3+D3)-H3 -> 7915.9646 | K3: =I3-H3 -> 1885.4167 | L3: =L2*(1+נתונים!B44)+J3 -> 320698.61 | M3: =M2*(1+נתונים!B44)+K3 -> 3785.8679 | N3: =F3-(נתונים!B4+נתונים!B21) -> 290000 | O3: =MAX(0,N3)*נתונים!B36*(1-נתונים!B37) -> 0 | P3: =G3-O3 -> 806745.39 | Q3: =G3-O3+M3 -> 810531.26 | R3: =L3 -> 320698.61
A4: 3 | B4: =ROUNDUP(A4/12,0) -> 1 | C4: =נתונים!B43 -> 14165.965 | D4: =נתונים!B27 -> 250 | E4: =INDEX(לוח_סילוקין!$F$2:$F$361,A4) -> 2689861.7 | F4: =נתונים!$B$5*(1+נתונים!$B$6)^(A4/12) -> 3500000 | G4: =F4-E4 -> 810138.34 | H4: =נתונים!B30*(1+נתונים!B31)^(B4-1) -> 6500 | I4: =נתונים!B32*(1-נתונים!B33/12)*(1+נתונים!B31)^(B4-1) -> 8385.4167 | J4: =(C4+D4)-H4 -> 7915.9646 | K4: =I4-H4 -> 1885.4167 | L4: =L3*(1+נתונים!B44)+J4 -> 331171.87 | M4: =M3*(1+נתונים!B44)+K4 -> 5701.4736 | N4: =F4-(נתונים!B4+נתונים!B21) -> 290000 | O4: =MAX(0,N4)*נתונים!B36*(1-נתונים!B37) -> 0 | P4: =G4-O4 -> 810138.34 | Q4: =G4-O4+M4 -> 815839.81 | R4: =L4 -> 331171.87
A5: 4 | B5: =ROUNDUP(A5/12,0) -> 1 | C5: =נתונים!B43 -> 14165.965 | D5: =נתונים!B27 -> 250 | E5: =INDEX(לוח_סילוקין!$F$2:$F$361,A5) -> 2686455.1 | F5: =נתונים!$B$5*(1+נתונים!$B$6)^(A5/12) -> 3500000 | G5: =F5-E5 -> 813544.86 | H5: =נתונים!B30*(1+נתונים!B31)^(B5-1) -> 6500 | I5: =נתונים!B32*(1-נתונים!B33/12)*(1+נתונים!B31)^(B5-1) -> 8385.4167 | J5: =(C5+D5)-H5 -> 7915.9646 | K5: =I5-H5 -> 1885.4167 | L5: =L4*(1+נתונים!B44)+J5 -> 341728.65 | M5: =M4*(1+נתונים!B44)+K5 -> 7632.3546 | N5: =F5-(נתונים!B4+נתונים!B21) -> 290000 | O5: =MAX(0,N5)*נתונים!B36*(1-נתונים!B37) -> 0 | P5: =G5-O5 -> 813544.86 | Q5: =G5-O5+M5 -> 821177.21 | R5: =L5 -> 341728.65
A6: 5 | B6: =ROUNDUP(A6/12,0) -> 1 | C6: =נתונים!B43 -> 14165.965 | D6: =נתונים!B27 -> 250 | E6: =INDEX(לוח_סילוקין!$F$2:$F$361,A6) -> 2683035 | F6: =נתונים!$B$5*(1+נתונים!$B$6)^(A6/12) -> 3500000 | G6: =F6-E6 -> 816965 | H6: =נתונים!B30*(1+נתונים!B31)^(B6-1) -> 6500 | I6: =נתונים!B32*(1-נתונים!B33/12)*(1+נתונים!B31)^(B6-1) -> 8385.4167 | J6: =(C6+D6)-H6 -> 7915.9646 | K6: =I6-H6 -> 1885.4167 | L6: =L5*(1+נתונים!B44)+J6 -> 352369.61 | M6: =M5*(1+נתונים!B44)+K6 -> 9578.6328 | N6: =F6-(נתונים!B4+נתונים!B21) -> 290000 | O6: =MAX(0,N6)*נתונים!B36*(1-נתונים!B37) -> 0 | P6: =G6-O6 -> 816965 | Q6: =G6-O6+M6 -> 826543.63 | R6: =L6 -> 352369.61
A7: 6 | B7: =ROUNDUP(A7/12,0) -> 1 | C7: =נתונים!B43 -> 14165.965 | D7: =נתונים!B27 -> 250 | E7: =INDEX(לוח_סילוקין!$F$2:$F$361,A7) -> 2679601.2 | F7: =נתונים!$B$5*(1+נתונים!$B$6)^(A7/12) -> 3500000 | G7: =F7-E7 -> 820398.83 | H7: =נתונים!B30*(1+נתונים!B31)^(B7-1) -> 6500 | I7: =נתונים!B32*(1-נתונים!B33/12)*(1+נתונים!B31)^(B7-1) -> 8385.4167 | J7: =(C7+D7)-H7 -> 7915.9646 | K7: =I7-H7 -> 1885.4167 | L7: =L6*(1+נתונים!B44)+J7 -> 363095.41 | M7: =M6*(1+נתונים!B44)+K7 -> 11540.431 | N7: =F7-(נתונים!B4+נתונים!B21) -> 290000 | O7: =MAX(0,N7)*נתונים!B36*(1-נתונים!B37) -> 0 | P7: =G7-O7 -> 820398.83 | Q7: =G7-O7+M7 -> 831939.26 | R7: =L7 -> 363095.41
A8: 7 | B8: =ROUNDUP(A8/12,0) -> 1 | C8: =נתונים!B43 -> 14165.965 | D8: =נתונים!B27 -> 250 | E8: =INDEX(לוח_סילוקין!$F$2:$F$361,A8) -> 2676153.6 | F8: =נתונים!$B$5*(1+נתונים!$B$6)^(A8/12) -> 3500000 | G8: =F8-E8 -> 823846.39 | H8: =נתונים!B30*(1+נתונים!B31)^(B8-1) -> 6500 | I8: =נתונים!B32*(1-נתונים!B33/12)*(1+נתונים!B31)^(B8-1) -> 8385.4167 | J8: =(C8+D8)-H8 -> 7915.9646 | K8: =I8-H8 -> 1885.4167 | L8: =L7*(1+נתונים!B44)+J8 -> 373906.75 | M8: =M7*(1+נתונים!B44)+K8 -> 13517.872 | N8: =F8-(נתונים!B4+נתונים!B21) -> 290000 | O8: =MAX(0,N8)*נתונים!B36*(1-נתונים!B37) -> 0 | P8: =G8-O8 -> 823846.39 | Q8: =G8-O8+M8 -> 837364.26 | R8: =L8 -> 373906.75
A9: 8 | B9: =ROUNDUP(A9/12,0) -> 1 | C9: =נתונים!B43 -> 14165.965 | D9: =נתונים!B27 -> 250 | E9: =INDEX(לוח_סילוקין!$F$2:$F$361,A9) -> 2672692.3 | F9: =נתונים!$B$5*(1+נתונים!$B$6)^(A9/12) -> 3500000 | G9: =F9-E9 -> 827307.74 | H9: =נתונים!B30*(1+נתונים!B31)^(B9-1) -> 6500 | I9: =נתונים!B32*(1-נתונים!B33/12)*(1+נתונים!B31)^(B9-1) -> 8385.4167 | J9: =(C9+D9)-H9 -> 7915.9646 | K9: =I9-H9 -> 1885.4167 | L9: =L8*(1+נתונים!B44)+J9 -> 384804.3 | M9: =M8*(1+נתונים!B44)+K9 -> 15511.083 | N9: =F9-(נתונים!B4+נתונים!B21) -> 290000 | O9: =MAX(0,N9)*נתונים!B36*(1-נתונים!B37) -> 0 | P9: =G9-O9 -> 827307.74 | Q9: =G9-O9+M9 -> 842818.82 | R9: =L9 -> 384804.3
A10: 9 | B10: =ROUNDUP(A10/12,0) -> 1 | C10: =נתונים!B43 -> 14165.965 | D10: =נתונים!B27 -> 250 | E10: =INDEX(לוח_סילוקין!$F$2:$F$361,A10) -> 2669217.1 | F10: =נתונים!$B$5*(1+נתונים!$B$6)^(A10/12) -> 3500000 | G10: =F10-E10 -> 830782.93 | H10: =נתונים!B30*(1+נתונים!B31)^(B10-1) -> 6500 | I10: =נתונים!B32*(1-נתונים!B33/12)*(1+נתונים!B31)^(B10-1) -> 8385.4167 | J10: =(C10+D10)-H10 -> 7915.9646 | K10: =I10-H10 -> 1885.4167 | L10: =L9*(1+נתונים!B44)+J10 -> 395788.75 | M10: =M9*(1+נתונים!B44)+K10 -> 17520.187 | N10: =F10-(נתונים!B4+נתונים!B21) -> 290000 | O10: =MAX(0,N10)*נתונים!B36*(1-נתונים!B37) -> 0 | P10: =G10-O10 -> 830782.93 | Q10: =G10-O10+M10 -> 848303.12 | R10: =L10 -> 395788.75
A11: 10 | B11: =ROUNDUP(A11/12,0) -> 1 | C11: =נתונים!B43 -> 14165.965 | D11: =נתונים!B27 -> 250 | E11: =INDEX(לוח_סילוקין!$F$2:$F$361,A11) -> 2665728 | F11: =נתונים!$B$5*(1+נתונים!$B$6)^(A11/12) -> 3500000 | G11: =F11-E11 -> 834272.03 | H11: =נתונים!B30*(1+נתונים!B31)^(B11-1) -> 6500 | I11: =נתונים!B32*(1-נתונים!B33/12)*(1+נתונים!B31)^(B11-1) -> 8385.4167 | J11: =(C11+D11)-H11 -> 7915.9646 | K11: =I11-H11 -> 1885.4167 | L11: =L10*(1+נתונים!B44)+J11 -> 406860.79 | M11: =M10*(1+נתונים!B44)+K11 -> 19545.312 | N11: =F11-(נתונים!B4+נתונים!B21) -> 290000 | O11: =MAX(0,N11)*נתונים!B36*(1-נתונים!B37) -> 0 | P11: =G11-O11 -> 834272.03 | Q11: =G11-O11+M11 -> 853817.34 | R11: =L11 -> 406860.79
A12: 11 | B12: =ROUNDUP(A12/12,0) -> 1 | C12: =נתונים!B43 -> 14165.965 | D12: =נתונים!B27 -> 250 | E12: =INDEX(לוח_סילוקין!$F$2:$F$361,A12) -> 2662224.9 | F12: =נתונים!$B$5*(1+נתונים!$B$6)^(A12/12) -> 3500000 | G12: =F12-E12 -> 837775.08 | H12: =נתונים!B30*(1+נתונים!B31)^(B12-1) -> 6500 | I12: =נתונים!B32*(1-נתונים!B33/12)*(1+נתונים!B31)^(B12-1) -> 8385.4167 | J12: =(C12+D12)-H12 -> 7915.9646 | K12: =I12-H12 -> 1885.4167 | L12: =L11*(1+נתונים!B44)+J12 -> 418021.12 | M12: =M11*(1+נתונים!B44)+K12 -> 21586.586 | N12: =F12-(נתונים!B4+נתונים!B21) -> 290000 | O12: =MAX(0,N12)*נתונים!B36*(1-נתונים!B37) -> 0 | P12: =G12-O12 -> 837775.08 | Q12: =G12-O12+M12 -> 859361.67 | R12: =L12 -> 418021.12
A13: 12 | B13: =ROUNDUP(A13/12,0) -> 1 | C13: =נתונים!B43 -> 14165.965 | D13: =נתונים!B27 -> 250 | E13: =INDEX(לוח_סילוקין!$F$2:$F$361,A13) -> 2658707.9 | F13: =נתונים!$B$5*(1+נתונים!$B$6)^(A13/12) -> 3500000 | G13: =F13-E13 -> 841292.14 | H13: =נתונים!B30*(1+נתונים!B31)^(B13-1) -> 6500 | I13: =נתונים!B32*(1-נתונים!B33/12)*(1+נתונים!B31)^(B13-1) -> 8385.4167 | J13: =(C13+D13)-H13 -> 7915.9646 | K13: =I13-H13 -> 1885.4167 | L13: =L12*(1+נתונים!B44)+J13 -> 429270.44 | M13: =M12*(1+נתונים!B44)+K13 -> 23644.137 | N13: =F13-(נתונים!B4+נתונים!B21) -> 290000 | O13: =MAX(0,N13)*נתונים!B36*(1-נתונים!B37) -> 0 | P13: =G13-O13 -> 841292.14 | Q13: =G13-O13+M13 -> 864936.28 | R13: =L13 -> 429270.44
A14: 13 | B14: =ROUNDUP(A14/12,0) -> 2 | C14: =נתונים!B43 -> 14165.965 | D14: =נתונים!B27 -> 250 | E14: =INDEX(לוח_סילוקין!$F$2:$F$361,A14) -> 2655176.7 | F14: =נתונים!$B$5*(1+נתונים!$B$6)^(A14/12) -> 3500000 | G14: =F14-E14 -> 844823.28 | H14: =נתונים!B30*(1+נתונים!B31)^(B14-1) -> 6630 | I14: =נתונים!B32*(1-נתונים!B33/12)*(1+נתונים!B31)^(B14-1) -> 8553.125 | J14: =(C14+D14)-H14 -> 7785.9646 | K14: =I14-H14 -> 1923.125 | L14: =L13*(1+נתונים!B44)+J14 -> 440479.47 | M14: =M13*(1+נתונים!B44)+K14 -> 25755.803 | N14: =F14-(נתונים!B4+נתונים!B21) -> 290000 | O14: =MAX(0,N14)*נתונים!B36*(1-נתונים!B37) -> 0 | P14: =G14-O14 -> 844823.28 | Q14: =G14-O14+M14 -> 870579.08 | R14: =L14 -> 440479.47
A15: 14 | B15: =ROUNDUP(A15/12,0) -> 2 | C15: =נתונים!B43 -> 14165.965 | D15: =נתונים!B27 -> 250 | E15: =INDEX(לוח_סילוקין!$F$2:$F$361,A15) -> 2651631.5 | F15: =נתונים!$B$5*(1+נתונים!$B$6)^(A15/12) -> 3500000 | G15: =F15-E15 -> 848368.54 | H15: =נתונים!B30*(1+נתונים!B31)^(B15-1) -> 6630 | I15: =נתונים!B32*(1-נתונים!B33/12)*(1+נתונים!B31)^(B15-1) -> 8553.125 | J15: =(C15+D15)-H15 -> 7785.9646 | K15: =I15-H15 -> 1923.125 | L15: =L14*(1+נתונים!B44)+J15 -> 451777.88 | M15: =M14*(1+נתונים!B44)+K15 -> 27884.309 | N15: =F15-(נתונים!B4+נתונים!B21) -> 290000 | O15: =MAX(0,N15)*נתונים!B36*(1-נתונים!B37) -> 0 | P15: =G15-O15 -> 848368.54 | Q15: =G15-O15+M15 -> 876252.84 | R15: =L15 -> 451777.88
A16: 15 | B16: =ROUNDUP(A16/12,0) -> 2 | C16: =נתונים!B43 -> 14165.965 | D16: =נתונים!B27 -> 250 | E16: =INDEX(לוח_סילוקין!$F$2:$F$361,A16) -> 2648072 | F16: =נתונים!$B$5*(1+נתונים!$B$6)^(A16/12) -> 3500000 | G16: =F16-E16 -> 851927.97 | H16: =נתונים!B30*(1+נתונים!B31)^(B16-1) -> 6630 | I16: =נתונים!B32*(1-נתונים!B33/12)*(1+נתונים!B31)^(B16-1) -> 8553.125 | J16: =(C16+D16)-H16 -> 7785.9646 | K16: =I16-H16 -> 1923.125 | L16: =L15*(1+נתונים!B44)+J16 -> 463166.39 | M16: =M15*(1+נתונים!B44)+K16 -> 30029.787 | N16: =F16-(נתונים!B4+נתונים!B21) -> 290000 | O16: =MAX(0,N16)*נתונים!B36*(1-נתונים!B37) -> 0 | P16: =G16-O16 -> 851927.97 | Q16: =G16-O16+M16 -> 881957.76 | R16: =L16 -> 463166.39
A17: 16 | B17: =ROUNDUP(A17/12,0) -> 2 | C17: =נתונים!B43 -> 14165.965 | D17: =נתונים!B27 -> 250 | E17: =INDEX(לוח_סילוקין!$F$2:$F$361,A17) -> 2644498.3 | F17: =נתונים!$B$5*(1+נתונים!$B$6)^(A17/12) -> 3500000 | G17: =F17-E17 -> 855501.65 | H17: =נתונים!B30*(1+נתונים!B31)^(B17-1) -> 6630 | I17: =נתונים!B32*(1-נתונים!B33/12)*(1+נתונים!B31)^(B17-1) -> 8553.125 | J17: =(C17+D17)-H17 -> 7785.9646 | K17: =I17-H17 -> 1923.125 | L17: =L16*(1+נתונים!B44)+J17 -> 474645.7 | M17: =M16*(1+נתונים!B44)+K17 -> 32192.374 | N17: =F17-(נתונים!B4+נתונים!B21) -> 290000 | O17: =MAX(0,N17)*נתונים!B36*(1-נתונים!B37) -> 0 | P17: =G17-O17 -> 855501.65 | Q17: =G17-O17+M17 -> 887694.02 | R17: =L17 -> 474645.7
A18: 17 | B18: =ROUNDUP(A18/12,0) -> 2 | C18: =נתונים!B43 -> 14165.965 | D18: =נתונים!B27 -> 250 | E18: =INDEX(לוח_סילוקין!$F$2:$F$361,A18) -> 2640910.4 | F18: =נתונים!$B$5*(1+נתונים!$B$6)^(A18/12) -> 3500000 | G18: =F18-E18 -> 859089.62 | H18: =נתונים!B30*(1+נתונים!B31)^(B18-1) -> 6630 | I18: =נתונים!B32*(1-נתונים!B33/12)*(1+נתונים!B31)^(B18-1) -> 8553.125 | J18: =(C18+D18)-H18 -> 7785.9646 | K18: =I18-H18 -> 1923.125 | L18: =L17*(1+נתונים!B44)+J18 -> 486216.56 | M18: =M17*(1+נתונים!B44)+K18 -> 34372.205 | N18: =F18-(נתונים!B4+נתונים!B21) -> 290000 | O18: =MAX(0,N18)*נתונים!B36*(1-נתונים!B37) -> 0 | P18: =G18-O18 -> 859089.62 | Q18: =G18-O18+M18 -> 893461.83 | R18: =L18 -> 486216.56
A19: 18 | B19: =ROUNDUP(A19/12,0) -> 2 | C19: =נתונים!B43 -> 14165.965 | D19: =נתונים!B27 -> 250 | E19: =INDEX(לוח_סילוקין!$F$2:$F$361,A19) -> 2637308.1 | F19: =נתונים!$B$5*(1+נתונים!$B$6)^(A19/12) -> 3500000 | G19: =F19-E19 -> 862691.95 | H19: =נתונים!B30*(1+נתונים!B31)^(B19-1) -> 6630 | I19: =נתונים!B32*(1-נתונים!B33/12)*(1+נתונים!B31)^(B19-1) -> 8553.125 | J19: =(C19+D19)-H19 -> 7785.9646 | K19: =I19-H19 -> 1923.125 | L19: =L18*(1+נתונים!B44)+J19 -> 497879.68 | M19: =M18*(1+נתונים!B44)+K19 -> 36569.419 | N19: =F19-(נתונים!B4+נתונים!B21) -> 290000 | O19: =MAX(0,N19)*נתונים!B36*(1-נתונים!B37) -> 0 | P19: =G19-O19 -> 862691.95 | Q19: =G19-O19+M19 -> 899261.36 | R19: =L19 -> 497879.68
A20: 19 | B20: =ROUNDUP(A20/12,0) -> 2 | C20: =נתונים!B43 -> 14165.965 | D20: =נתונים!B27 -> 250 | E20: =INDEX(לוח_סילוקין!$F$2:$F$361,A20) -> 2633691.3 | F20: =נתונים!$B$5*(1+נתונים!$B$6)^(A20/12) -> 3500000 | G20: =F20-E20 -> 866308.68 | H20: =נתונים!B30*(1+נתונים!B31)^(B20-1) -> 6630 | I20: =נתונים!B32*(1-נתונים!B33/12)*(1+נתונים!B31)^(B20-1) -> 8553.125 | J20: =(C20+D20)-H20 -> 7785.9646 | K20: =I20-H20 -> 1923.125 | L20: =L19*(1+נתונים!B44)+J20 -> 509635.81 | M20: =M19*(1+נתונים!B44)+K20 -> 38784.154 | N20: =F20-(נתונים!B4+נתונים!B21) -> 290000 | O20: =MAX(0,N20)*נתונים!B36*(1-נתונים!B37) -> 0 | P20: =G20-O20 -> 866308.68 | Q20: =G20-O20+M20 -> 905092.83 | R20: =L20 -> 509635.81
A21: 20 | B21: =ROUNDUP(A21/12,0) -> 2 | C21: =נתונים!B43 -> 14165.965 | D21: =נתונים!B27 -> 250 | E21: =INDEX(לוח_סילוקין!$F$2:$F$361,A21) -> 2630060.1 | F21: =נתונים!$B$5*(1+נתונים!$B$6)^(A21/12) -> 3500000 | G21: =F21-E21 -> 869939.88 | H21: =נתונים!B30*(1+נתונים!B31)^(B21-1) -> 6630 | I21: =נתונים!B32*(1-נתונים!B33/12)*(1+נתונים!B31)^(B21-1) -> 8553.125 | J21: =(C21+D21)-H21 -> 7785.9646 | K21: =I21-H21 -> 1923.125 | L21: =L20*(1+נתונים!B44)+J21 -> 521485.68 | M21: =M20*(1+נתונים!B44)+K21 -> 41016.549 | N21: =F21-(נתונים!B4+נתונים!B21) -> 290000 | O21: =MAX(0,N21)*נתונים!B36*(1-נתונים!B37) -> 0 | P21: =G21-O21 -> 869939.88 | Q21: =G21-O21+M21 -> 910956.43 | R21: =L21 -> 521485.68
A22: 21 | B22: =ROUNDUP(A22/12,0) -> 2 | C22: =נתונים!B43 -> 14165.965 | D22: =נתונים!B27 -> 250 | E22: =INDEX(לוח_סילוקין!$F$2:$F$361,A22) -> 2626414.4 | F22: =נתונים!$B$5*(1+נתונים!$B$6)^(A22/12) -> 3500000 | G22: =F22-E22 -> 873585.6 | H22: =נתונים!B30*(1+נתונים!B31)^(B22-1) -> 6630 | I22: =נתונים!B32*(1-נתונים!B33/12)*(1+נתונים!B31)^(B22-1) -> 8553.125 | J22: =(C22+D22)-H22 -> 7785.9646 | K22: =I22-H22 -> 1923.125 | L22: =L21*(1+נתונים!B44)+J22 -> 533430.05 | M22: =M21*(1+נתונים!B44)+K22 -> 43266.746 | N22: =F22-(נתונים!B4+נתונים!B21) -> 290000 | O22: =MAX(0,N22)*נתונים!B36*(1-נתונים!B37) -> 0 | P22: =G22-O22 -> 873585.6 | Q22: =G22-O22+M22 -> 916852.35 | R22: =L22 -> 533430.05
A23: 22 | B23: =ROUNDUP(A23/12,0) -> 2 | C23: =נתונים!B43 -> 14165.965 | D23: =נתונים!B27 -> 250 | E23: =INDEX(לוח_סילוקין!$F$2:$F$361,A23) -> 2622754.1 | F23: =נתונים!$B$5*(1+נתונים!$B$6)^(A23/12) -> 3500000 | G23: =F23-E23 -> 877245.91 | H23: =נתונים!B30*(1+נתונים!B31)^(B23-1) -> 6630 | I23: =נתונים!B32*(1-נתונים!B33/12)*(1+נתונים!B31)^(B23-1) -> 8553.125 | J23: =(C23+D23)-H23 -> 7785.9646 | K23: =I23-H23 -> 1923.125 | L23: =L22*(1+נתונים!B44)+J23 -> 545469.66 | M23: =M22*(1+נתונים!B44)+K23 -> 45534.886 | N23: =F23-(נתונים!B4+נתונים!B21) -> 290000 | O23: =MAX(0,N23)*נתונים!B36*(1-נתונים!B37) -> 0 | P23: =G23-O23 -> 877245.91 | Q23: =G23-O23+M23 -> 922780.79 | R23: =L23 -> 545469.66
A24: 23 | B24: =ROUNDUP(A24/12,0) -> 2 | C24: =נתונים!B43 -> 14165.965 | D24: =נתונים!B27 -> 250 | E24: =INDEX(לוח_סילוקין!$F$2:$F$361,A24) -> 2619079.1 | F24: =נתונים!$B$5*(1+נתונים!$B$6)^(A24/12) -> 3500000 | G24: =F24-E24 -> 880920.86 | H24: =נתונים!B30*(1+נתונים!B31)^(B24-1) -> 6630 | I24: =נתונים!B32*(1-נתונים!B33/12)*(1+נתונים!B31)^(B24-1) -> 8553.125 | J24: =(C24+D24)-H24 -> 7785.9646 | K24: =I24-H24 -> 1923.125 | L24: =L23*(1+נתונים!B44)+J24 -> 557605.27 | M24: =M23*(1+נתונים!B44)+K24 -> 47821.113 | N24: =F24-(נתונים!B4+נתונים!B21) -> 290000 | O24: =MAX(0,N24)*נתונים!B36*(1-נתונים!B37) -> 0 | P24: =G24-O24 -> 880920.86 | Q24: =G24-O24+M24 -> 928741.97 | R24: =L24 -> 557605.27
A25: 24 | B25: =ROUNDUP(A25/12,0) -> 2 | C25: =נתונים!B43 -> 14165.965 | D25: =נתונים!B27 -> 250 | E25: =INDEX(לוח_סילוקין!$F$2:$F$361,A25) -> 2615389.5 | F25: =נתונים!$B$5*(1+נתונים!$B$6)^(A25/12) -> 3500000 | G25: =F25-E25 -> 884610.5 | H25: =נתונים!B30*(1+נתונים!B31)^(B25-1) -> 6630 | I25: =נתונים!B32*(1-נתונים!B33/12)*(1+נתונים!B31)^(B25-1) -> 8553.125 | J25: =(C25+D25)-H25 -> 7785.9646 | K25: =I25-H25 -> 1923.125 | L25: =L24*(1+נתונים!B44)+J25 -> 569837.66 | M25: =M24*(1+נתונים!B44)+K25 -> 50125.57 | N25: =F25-(נתונים!B4+נתונים!B21) -> 290000 | O25: =MAX(0,N25)*נתונים!B36*(1-נתונים!B37) -> 0 | P25: =G25-O25 -> 884610.5 | Q25: =G25-O25+M25 -> 934736.07 | R25: =L25 -> 569837.66
A26: 25 | B26: =ROUNDUP(A26/12,0) -> 3 | C26: =נתונים!B43 -> 14165.965 | D26: =נתונים!B27 -> 250 | E26: =INDEX(לוח_סילוקין!$F$2:$F$361,A26) -> 2611685.1 | F26: =נתונים!$B$5*(1+נתונים!$B$6)^(A26/12) -> 3500000 | G26: =F26-E26 -> 888314.91 | H26: =נתונים!B30*(1+נתונים!B31)^(B26-1) -> 6762.6 | I26: =נתונים!B32*(1-נתונים!B33/12)*(1+נתונים!B31)^(B26-1) -> 8724.1875 | J26: =(C26+D26)-H26 -> 7653.3646 | K26: =I26-H26 -> 1961.5875 | L26: =L25*(1+נתונים!B44)+J26 -> 582034.99 | M26: =M25*(1+נתונים!B44)+K26 -> 52486.866 | N26: =F26-(נתונים!B4+נתונים!B21) -> 290000 | O26: =MAX(0,N26)*נתונים!B36*(1-נתונים!B37) -> 0 | P26: =G26-O26 -> 888314.91 | Q26: =G26-O26+M26 -> 940801.78 | R26: =L26 -> 582034.99
A27: 26 | B27: =ROUNDUP(A27/12,0) -> 3 | C27: =נתונים!B43 -> 14165.965 | D27: =נתונים!B27 -> 250 | E27: =INDEX(לוח_סילוקין!$F$2:$F$361,A27) -> 2607965.9 | F27: =נתונים!$B$5*(1+נתונים!$B$6)^(A27/12) -> 3500000 | G27: =F27-E27 -> 892034.13 | H27: =נתונים!B30*(1+נתונים!B31)^(B27-1) -> 6762.6 | I27: =נתונים!B32*(1-נתונים!B33/12)*(1+נתונים!B31)^(B27-1) -> 8724.1875 | J27: =(C27+D27)-H27 -> 7653.3646 | K27: =I27-H27 -> 1961.5875 | L27: =L26*(1+נתונים!B44)+J27 -> 594329.58 | M27: =M26*(1+נתונים!B44)+K27 -> 54866.991 | N27: =F27-(נתונים!B4+נתונים!B21) -> 290000 | O27: =MAX(0,N27)*נתונים!B36*(1-נתונים!B37) -> 0 | P27: =G27-O27 -> 892034.13 | Q27: =G27-O27+M27 -> 946901.13 | R27: =L27 -> 594329.58
A28: 27 | B28: =ROUNDUP(A28/12,0) -> 3 | C28: =נתונים!B43 -> 14165.965 | D28: =נתונים!B27 -> 250 | E28: =INDEX(לוח_סילוקין!$F$2:$F$361,A28) -> 2604231.8 | F28: =נתונים!$B$5*(1+נתונים!$B$6)^(A28/12) -> 3500000 | G28: =F28-E28 -> 895768.24 | H28: =נתונים!B30*(1+נתונים!B31)^(B28-1) -> 6762.6 | I28: =נתונים!B32*(1-נתונים!B33/12)*(1+נתונים!B31)^(B28-1) -> 8724.1875 | J28: =(C28+D28)-H28 -> 7653.3646 | K28: =I28-H28 -> 1961.5875 | L28: =L27*(1+נתונים!B44)+J28 -> 606722.22 | M28: =M27*(1+נתונים!B44)+K28 -> 57266.095 | N28: =F28-(נתונים!B4+נתונים!B21) -> 290000 | O28: =MAX(0,N28)*נתונים!B36*(1-נתונים!B37) -> 0 | P28: =G28-O28 -> 895768.24 | Q28: =G28-O28+M28 -> 953034.33 | R28: =L28 -> 606722.22
A29: 28 | B29: =ROUNDUP(A29/12,0) -> 3 | C29: =נתונים!B43 -> 14165.965 | D29: =נתונים!B27 -> 250 | E29: =INDEX(לוח_סילוקין!$F$2:$F$361,A29) -> 2600482.7 | F29: =נתונים!$B$5*(1+נתונים!$B$6)^(A29/12) -> 3500000 | G29: =F29-E29 -> 899517.27 | H29: =נתונים!B30*(1+נתונים!B31)^(B29-1) -> 6762.6 | I29: =נתונים!B32*(1-נתונים!B33/12)*(1+נתונים!B31)^(B29-1) -> 8724.1875 | J29: =(C29+D29)-H29 -> 7653.3646 | K29: =I29-H29 -> 1961.5875 | L29: =L28*(1+נתונים!B44)+J29 -> 619213.67 | M29: =M28*(1+נתונים!B44)+K29 -> 59684.331 | N29: =F29-(נתונים!B4+נתונים!B21) -> 290000 | O29: =MAX(0,N29)*נתונים!B36*(1-נתונים!B37) -> 0 | P29: =G29-O29 -> 899517.27 | Q29: =G29-O29+M29 -> 959201.6 | R29: =L29 -> 619213.67
A30: 29 | B30: =ROUNDUP(A30/12,0) -> 3 | C30: =נתונים!B43 -> 14165.965 | D30: =נתונים!B27 -> 250 | E30: =INDEX(לוח_סילוקין!$F$2:$F$361,A30) -> 2596718.7 | F30: =נתונים!$B$5*(1+נתונים!$B$6)^(A30/12) -> 3500000 | G30: =F30-E30 -> 903281.31 | H30: =נתונים!B30*(1+נתונים!B31)^(B30-1) -> 6762.6 | I30: =נתונים!B32*(1-נתונים!B33/12)*(1+נתונים!B31)^(B30-1) -> 8724.1875 | J30: =(C30+D30)-H30 -> 7653.3646 | K30: =I30-H30 -> 1961.5875 | L30: =L29*(1+נתונים!B44)+J30 -> 631804.73 | M30: =M29*(1+נתונים!B44)+K30 -> 62121.85 | N30: =F30-(נתונים!B4+נתונים!B21) -> 290000 | O30: =MAX(0,N30)*נתונים!B36*(1-נתונים!B37) -> 0 | P30: =G30-O30 -> 903281.31 | Q30: =G30-O30+M30 -> 965403.16 | R30: =L30 -> 631804.73
A31: 30 | B31: =ROUNDUP(A31/12,0) -> 3 | C31: =נתונים!B43 -> 14165.965 | D31: =נתונים!B27 -> 250 | E31: =INDEX(לוח_סילוקין!$F$2:$F$361,A31) -> 2592939.6 | F31: =נתונים!$B$5*(1+נתונים!$B$6)^(A31/12) -> 3500000 | G31: =F31-E31 -> 907060.4 | H31: =נתונים!B30*(1+נתונים!B31)^(B31-1) -> 6762.6 | I31: =נתונים!B32*(1-נתונים!B33/12)*(1+נתונים!B31)^(B31-1) -> 8724.1875 | J31: =(C31+D31)-H31 -> 7653.3646 | K31: =I31-H31 -> 1961.5875 | L31: =L30*(1+נתונים!B44)+J31 -> 644496.2 | M31: =M30*(1+נתונים!B44)+K31 -> 64578.805 | N31: =F31-(נתונים!B4+נתונים!B21) -> 290000 | O31: =MAX(0,N31)*נתונים!B36*(1-נתונים!B37) -> 0 | P31: =G31-O31 -> 907060.4 | Q31: =G31-O31+M31 -> 971639.2 | R31: =L31 -> 644496.2
A32: 31 | B32: =ROUNDUP(A32/12,0) -> 3 | C32: =נתונים!B43 -> 14165.965 | D32: =נתונים!B27 -> 250 | E32: =INDEX(לוח_סילוקין!$F$2:$F$361,A32) -> 2589145.4 | F32: =נתונים!$B$5*(1+נתונים!$B$6)^(A32/12) -> 3500000 | G32: =F32-E32 -> 910854.6 | H32: =נתונים!B30*(1+נתונים!B31)^(B32-1) -> 6762.6 | I32: =נתונים!B32*(1-נתונים!B33/12)*(1+נתונים!B31)^(B32-1) -> 8724.1875 | J32: =(C32+D32)-H32 -> 7653.3646 | K32: =I32-H32 -> 1961.5875 | L32: =L31*(1+נתונים!B44)+J32 -> 657288.86 | M32: =M31*(1+נתונים!B44)+K32 -> 67055.353 | N32: =F32-(נתונים!B4+נתונים!B21) -> 290000 | O32: =MAX(0,N32)*נתונים!B36*(1-נתונים!B37) -> 0 | P32: =G32-O32 -> 910854.6 | Q32: =G32-O32+M32 -> 977909.96 | R32: =L32 -> 657288.86
A33: 32 | B33: =ROUNDUP(A33/12,0) -> 3 | C33: =נתונים!B43 -> 14165.965 | D33: =נתונים!B27 -> 250 | E33: =INDEX(לוח_סילוקין!$F$2:$F$361,A33) -> 2585336 | F33: =נתונים!$B$5*(1+נתונים!$B$6)^(A33/12) -> 3500000 | G33: =F33-E33 -> 914663.99 | H33: =נתונים!B30*(1+נתונים!B31)^(B33-1) -> 6762.6 | I33: =נתונים!B32*(1-נתונים!B33/12)*(1+נתונים!B31)^(B33-1) -> 8724.1875 | J33: =(C33+D33)-H33 -> 7653.3646 | K33: =I33-H33 -> 1961.5875 | L33: =L32*(1+נתונים!B44)+J33 -> 670183.54 | M33: =M32*(1+נתונים!B44)+K33 -> 69551.65 | N33: =F33-(נתונים!B4+נתונים!B21) -> 290000 | O33: =MAX(0,N33)*נתונים!B36*(1-נתונים!B37) -> 0 | P33: =G33-O33 -> 914663.99 | Q33: =G33-O33+M33 -> 984215.64 | R33: =L33 -> 670183.54
A34: 33 | B34: =ROUNDUP(A34/12,0) -> 3 | C34: =נתונים!B43 -> 14165.965 | D34: =נתונים!B27 -> 250 | E34: =INDEX(לוח_סילוקין!$F$2:$F$361,A34) -> 2581511.4 | F34: =נתונים!$B$5*(1+נתונים!$B$6)^(A34/12) -> 3500000 | G34: =F34-E34 -> 918488.61 | H34: =נתונים!B30*(1+נתונים!B31)^(B34-1) -> 6762.6 | I34: =נתונים!B32*(1-נתונים!B33/12)*(1+נתונים!B31)^(B34-1) -> 8724.1875 | J34: =(C34+D34)-H34 -> 7653.3646 | K34: =I34-H34 -> 1961.5875 | L34: =L33*(1+נתונים!B44)+J34 -> 683181.04 | M34: =M33*(1+נתונים!B44)+K34 -> 72067.852 | N34: =F34-(נתונים!B4+נתונים!B21) -> 290000 | O34: =MAX(0,N34)*נתונים!B36*(1-נתונים!B37) -> 0 | P34: =G34-O34 -> 918488.61 | Q34: =G34-O34+M34 -> 990556.46 | R34: =L34 -> 683181.04
A35: 34 | B35: =ROUNDUP(A35/12,0) -> 3 | C35: =נתונים!B43 -> 14165.965 | D35: =נתונים!B27 -> 250 | E35: =INDEX(לוח_סילוקין!$F$2:$F$361,A35) -> 2577671.5 | F35: =נתונים!$B$5*(1+נתונים!$B$6)^(A35/12) -> 3500000 | G35: =F35-E35 -> 922328.53 | H35: =נתונים!B30*(1+נתונים!B31)^(B35-1) -> 6762.6 | I35: =נתונים!B32*(1-נתונים!B33/12)*(1+נתונים!B31)^(B35-1) -> 8724.1875 | J35: =(C35+D35)-H35 -> 7653.3646 | K35: =I35-H35 -> 1961.5875 | L35: =L34*(1+נתונים!B44)+J35 -> 696282.19 | M35: =M34*(1+נתונים!B44)+K35 -> 74604.118 | N35: =F35-(נתונים!B4+נתונים!B21) -> 290000 | O35: =MAX(0,N35)*נתונים!B36*(1-נתונים!B37) -> 0 | P35: =G35-O35 -> 922328.53 | Q35: =G35-O35+M35 -> 996932.64 | R35: =L35 -> 696282.19
A36: 35 | B36: =ROUNDUP(A36/12,0) -> 3 | C36: =נתונים!B43 -> 14165.965 | D36: =נתונים!B27 -> 250 | E36: =INDEX(לוח_סילוקין!$F$2:$F$361,A36) -> 2573816.2 | F36: =נתונים!$B$5*(1+נתונים!$B$6)^(A36/12) -> 3500000 | G36: =F36-E36 -> 926183.8 | H36: =נתונים!B30*(1+נתונים!B31)^(B36-1) -> 6762.6 | I36: =נתונים!B32*(1-נתונים!B33/12)*(1+נתונים!B31)^(B36-1) -> 8724.1875 | J36: =(C36+D36)-H36 -> 7653.3646 | K36: =I36-H36 -> 1961.5875 | L36: =L35*(1+נתונים!B44)+J36 -> 709487.81 | M36: =M35*(1+נתונים!B44)+K36 -> 77160.61 | N36: =F36-(נתונים!B4+נתונים!B21) -> 290000 | O36: =MAX(0,N36)*נתונים!B36*(1-נתונים!B37) -> 0 | P36: =G36-O36 -> 926183.8 | Q36: =G36-O36+M36 -> 1003344.4 | R36: =L36 -> 709487.81
A37: 36 | B37: =ROUNDUP(A37/12,0) -> 3 | C37: =נתונים!B43 -> 14165.965 | D37: =נתונים!B27 -> 250 | E37: =INDEX(לוח_סילוקין!$F$2:$F$361,A37) -> 2569945.5 | F37: =נתונים!$B$5*(1+נתונים!$B$6)^(A37/12) -> 3500000 | G37: =F37-E37 -> 930054.5 | H37: =נתונים!B30*(1+נתונים!B31)^(B37-1) -> 6762.6 | I37: =נתונים!B32*(1-נתונים!B33/12)*(1+נתונים!B31)^(B37-1) -> 8724.1875 | J37: =(C37+D37)-H37 -> 7653.3646 | K37: =I37-H37 -> 1961.5875 | L37: =L36*(1+נתונים!B44)+J37 -> 722798.73 | M37: =M36*(1+נתונים!B44)+K37 -> 79737.487 | N37: =F37-(נתונים!B4+נתונים!B21) -> 290000 | O37: =MAX(0,N37)*נתונים!B36*(1-נתונים!B37) -> 0 | P37: =G37-O37 -> 930054.5 | Q37: =G37-O37+M37 -> 1009792 | R37: =L37 -> 722798.73
A38: 37 | B38: =ROUNDUP(A38/12,0) -> 4 | C38: =נתונים!B43 -> 14165.965 | D38: =נתונים!B27 -> 250 | E38: =INDEX(לוח_סילוקין!$F$2:$F$361,A38) -> 2566059.3 | F38: =נתונים!$B$5*(1+נתונים!$B$6)^(A38/12) -> 3500000 | G38: =F38-E38 -> 933940.69 | H38: =נתונים!B30*(1+נתונים!B31)^(B38-1) -> 6897.852 | I38: =נתונים!B32*(1-נתונים!B33/12)*(1+נתונים!B31)^(B38-1) -> 8898.6713 | J38: =(C38+D38)-H38 -> 7518.1126 | K38: =I38-H38 -> 2000.8193 | L38: =L37*(1+נתונים!B44)+J38 -> 736080.54 | M38: =M37*(1+נתונים!B44)+K38 -> 82374.144 | N38: =F38-(נתונים!B4+נתונים!B21) -> 290000 | O38: =MAX(0,N38)*נתונים!B36*(1-נתונים!B37) -> 0 | P38: =G38-O38 -> 933940.69 | Q38: =G38-O38+M38 -> 1016314.8 | R38: =L38 -> 736080.54
A39: 38 | B39: =ROUNDUP(A39/12,0) -> 4 | C39: =נתונים!B43 -> 14165.965 | D39: =נתונים!B27 -> 250 | E39: =INDEX(לוח_סילוקין!$F$2:$F$361,A39) -> 2562157.6 | F39: =נתונים!$B$5*(1+נתונים!$B$6)^(A39/12) -> 3500000 | G39: =F39-E39 -> 937842.41 | H39: =נתונים!B30*(1+נתונים!B31)^(B39-1) -> 6897.852 | I39: =נתונים!B32*(1-נתונים!B33/12)*(1+נתונים!B31)^(B39-1) -> 8898.6713 | J39: =(C39+D39)-H39 -> 7518.1126 | K39: =I39-H39 -> 2000.8193 | L39: =L38*(1+נתונים!B44)+J39 -> 749468.26 | M39: =M38*(1+נתונים!B44)+K39 -> 85031.826 | N39: =F39-(נתונים!B4+נתונים!B21) -> 290000 | O39: =MAX(0,N39)*נתונים!B36*(1-נתונים!B37) -> 0 | P39: =G39-O39 -> 937842.41 | Q39: =G39-O39+M39 -> 1022874.2 | R39: =L39 -> 749468.26
A40: 39 | B40: =ROUNDUP(A40/12,0) -> 4 | C40: =נתונים!B43 -> 14165.965 | D40: =נתונים!B27 -> 250 | E40: =INDEX(לוח_סילוקין!$F$2:$F$361,A40) -> 2558240.3 | F40: =נתונים!$B$5*(1+נתונים!$B$6)^(A40/12) -> 3500000 | G40: =F40-E40 -> 941759.75 | H40: =נתונים!B30*(1+נתונים!B31)^(B40-1) -> 6897.852 | I40: =נתונים!B32*(1-נתונים!B33/12)*(1+נתונים!B31)^(B40-1) -> 8898.6713 | J40: =(C40+D40)-H40 -> 7518.1126 | K40: =I40-H40 -> 2000.8193 | L40: =L39*(1+נתונים!B44)+J40 -> 762962.74 | M40: =M39*(1+נתונים!B44)+K40 -> 87710.701 | N40: =F40-(נתונים!B4+נתונים!B21) -> 290000 | O40: =MAX(0,N40)*נתונים!B36*(1-נתונים!B37) -> 0 | P40: =G40-O40 -> 941759.75 | Q40: =G40-O40+M40 -> 1029470.4 | R40: =L40 -> 762962.74
...

Sheet דשבורד
A1: דשבורד השוואה - מחיר מטרה מול S&P 500
A3: הסבר שלושת המסלולים:
A4: מסלול A - "גר בדירה": קונים את דירת מחיר מטרה וגרים בה. השווי הנטו = הון עצמי בדירה (שווי שוק פחות יתרת משכנתא).
A5: מסלול B - "משכיר": קונים את הדירה אך משכירים אותה, וגרים בשכירות במקום אחר. השווי הנטו = הון עצמי בדירה (נטו ממס שבח) + תיק השקעות שמתחיל מ-600 אלף ש"ח (ההון העצמי) ונובע מהפרש תזרים (הכנסה משכירות פחות הוצאות הדירה פחות שכר הדירה ששולם).
A6: מסלול C - "לא קונים": לא משתתפים בהגרלה, ממשיכים לגור בשכירות, ומשקיעים את ההון העצמי (600 אלף ש"ח לפי הדוגמה) ב-S&P 500, בתוספת הפרש חודשי בין עלות "הדירה" (משכנתא+הוצאות) לשכר הדירה בפועל. ההוצאות החד-פעמיות (מדד תשומות, שדרוגים וכו') ממומנות בנפרד ולכן לא מנוכות מסכום ההשקעה הראשוני.
A7: מס שבח: בדף "נתונים" ניתן להגדיר את שיעור המס ואת הפטור (דירה יחידה). אם יש פטור (1), הוא לא מנוכה מהשווי הנטו. אם אין פטור (0), מנוכה מס על הרווח (שווי הדירה בעתיד פחות מחיר רכישה ועלויות חד-פעמיות) במסלולים A ו-B.
A9: שנה | B9: מסלול A - גר בדירה | C9: מסלול B - משכיר | D9: מסלול C - לא קונה (S&P) | E9: A-C | F9: B-C
A10: 1 | B10: =השוואה_חודשית!P13 -> 841292.14 | C10: =השוואה_חודשית!Q13 -> 864936.28 | D10: =השוואה_חודשית!R13 -> 429270.44 | E10: =B10-D10 -> 412021.7 | F10: =C10-D10 -> 435665.84
A11: 2 | B11: =השוואה_חודשית!P25 -> 884610.5 | C11: =השוואה_חודשית!Q25 -> 934736.07 | D11: =השוואה_חודשית!R25 -> 569837.66 | E11: =B11-D11 -> 314772.84 | F11: =C11-D11 -> 364898.41
A12: 3 | B12: =השוואה_חודשית!P37 -> 930054.5 | C12: =השוואה_חודשית!Q37 -> 1009792 | D12: =השוואה_חודשית!R37 -> 722798.73 | E12: =B12-D12 -> 207255.78 | F12: =C12-D12 -> 286993.26
A13: 4 | B13: =השוואה_חודשית!P49 -> 977728.45 | C13: =השוואה_חודשית!Q49 -> 1090531 | D13: =השוואה_חודשית!R49 -> 889359.76 | E13: =B13-D13 -> 88368.686 | F13: =C13-D13 -> 201171.27
A14: 5 | B14: =השוואה_חודשית!P61 -> 1027741.8 | C14: =השוואה_חודשית!Q61 -> 1177417.8 | D14: =השוואה_חודשית!R61 -> 1070846.9 | E14: =B14-D14 -> -43105.084 | F14: =C14-D14 -> 106570.93
A15: 6 | B15: =השוואה_חודשית!P73 -> 1080209.2 | C15: =השוואה_חודשית!Q73 -> 1270957.9 | D15: =השוואה_חודשית!R73 -> 1268718 | E15: =B15-D15 -> -188508.74 | F15: =C15-D15 -> 2239.9106
A16: 7 | B16: =השוואה_חודשית!P85 -> 1135251.3 | C16: =השוואה_חודשית!Q85 -> 1371702 | D16: =השוואה_חודשית!R85 -> 1484576.3 | E16: =B16-D16 -> -349324.98 | F16: =C16-D16 -> -112874.32
A18: סיכום שנה אחרונה
A19: שווי נטו לאחר תקופת ההחזקה | B19: =B16 -> 1135251.3 | C19: =C16 -> 1371702 | D19: =D16 -> 1484576.3
A20: הפרש B מול A | B20: =C16-B16 -> 236450.66
A21: הפרש C מול A | B21: =D16-B16 -> 349324.98
A22: המסלול המנצח | B22: =IF(AND(B16>=C16,B16>=D16),"מסלול A - גר בדירה",IF(AND(C16>=B16,C16>=D16),"מסלול B - משכיר","מסלול C - לא קונה (S&P)")) -> מסלול C - לא קונה (S&P)
A24: שנה ראשונה בה מסלול C עוקף את מסלול A | B24: =IFERROR(INDEX(A10:A16,MATCH(TRUE(),INDEX(D10:D16>B10:B16,0),0)),"לא קורה בטווח שנבדק") -> 5
